Workbook

Sheet Respuestas de formulario 1
A1: Marca temporal | B1: ¿Pagas actualmente al menos una suscripción mensual o anual? | C1: P2. ¿Cuántas suscripciones de pago tienes actualmente? | D1: P3. ¿Cuáles tienes? (marca todas las que correspondan) | E1: P4. ¿Cómo las pagas principalmente? | F1: P5. Sin revisar tu banco ni tus apps, ¿cuánto crees que gastas al mes en total en suscripciones? | G1: P6. ¿Qué tan seguro estás de esa cifra? | H1: P7. ¿Alguna vez has sumado de verdad cuánto gastas al mes en suscripciones? | I1: P8. Ahora sí: tómate un minuto, revisa tu banco o tus apps y dinos el total REAL. | J1: P9. ¿Has pagado alguna vez por una suscripción que no estabas usando? | K1: P10. Si te pasó, ¿cuánto tiempo seguiste pagando sin usarla? | L1: P11. De las suscripciones que tienes hoy, ¿cuántas sientes que no valen lo que pagas? | M1: P12. La suscripción que MENOS usas, ¿cuándo la usaste por última vez? | N1: P13. ¿Te ha pasado que terminó una prueba gratis y te cobraron sin darte cuenta? | O1: P14. ¿Has dejado de usar algo pero seguiste pagando por flojera o por no saber cómo cancelarlo? | P1: P15. Cuando has querido cancelar una suscripción, ¿qué tan difícil te ha resultado? | Q1: P16. ¿Compartes alguna suscripción con familia o amigos? | R1: P17. Si compartes, ¿has tenido problemas para cobrar o para llevar la cuenta de quién paga qué? | S1: P18. ¿Qué haces hoy para llevar el control de tus suscripciones? | T1: P19. ¿Qué te ayudaría más? (elige máximo 2) | U1: P20. Si una app te ahorrara $15.000 al mes, ¿cuánto estarías dispuesto a pagar por ella? | V1: P21. ¿En qué dispositivos la usarías? | W1: P22. ¿Cuál es tu edad? | X1: P23. ¿Cuál es tu situación actual? | Y1: P24. ¿Algo más que quieras contarnos sobre tus suscripciones? | Z1: P25. Si te gustaría probar la app cuando esté lista, déjanos tu correo
A2: 46248.841 | B2: Sí | C2: 5 o 6 | D2: Netflix, Disney+, YouTube Premium, iCloud o Google One, ChatGPT u otra IA, Gimnasio | E2: Algunas las comparto con familia o amigos | F2: Entre $35.000 y $50.000 | G2: 3 | H2: Nunca lo he hecho | I2: Más de $80.000 | J2: Sí, varias veces | K2: Entre 1 y 3 meses | L2: 2 | M2: Este mes | N2: Sí, más de una vez | O2: Sí | P2: 5 | Q2: No | R2: No comparto ninguna | S2: Nada, no llevo control | T2: Ver el total que gasto al mes, Que me avise antes de cada cobro, Que me avise antes de que termine una prueba gratis | U2: Entre $1.000 y $3.000 al mes | V2: Celular | W2: 18 a 24 | X2: Estudio y trabajo
A3: 46248.843 | B3: Sí | C3: 1 o 2 | D3: Spotify | E3: Todas las pago yo | F3: Menos de $10.000 | G3: 5 | H3: Lo hice una vez | I3: Menos de $10.000 | J3: No, nunca | K3: No me ha pasado | L3: Ninguna | M3: Esta semana | N3: No, nunca | O3: No | P3: 2 | Q3: No | R3: No comparto ninguna | S3: Lo tengo más o menos en la cabeza | T3: Que me avise antes de cada cobro | U3: Hasta $1.000 al mes | V3: Celular | W3: 18 a 24 | X3: Solo trabajo | Y3: Solo tengo Spotify con descuento de estudiante | Z3: Convenceme
A4: 46248.851 | B4: Sí | C4: 7 a 9 | D4: Netflix, Spotify, Disney+, HBO Max, YouTube Premium, ChatGPT u otra IA, Juegos (PS Plus, Game Pass, etc.) | E4: Algunas las comparto con familia o amigos | F4: Entre $50.000 y $80.000 | G4: 3 | H4: Nunca lo he hecho | J4: Sí, varias veces | K4: Entre 1 y 3 meses | L4: 1 | M4: Este mes | N4: Sí, más de una vez | O4: No | P4: 3 | Q4: Sí | R4: Nunca | S4: Anoto en Excel o en notas del celular | T4: Que me avise antes de cada cobro, Mostrarme cuánto uso realmente cada una | U4: Prefiero un pago único | V4: Computador | W4: 25 a 34 | X4: Solo trabajo
A5: 46248.871 | B5: No
A6: 46248.882 | B6: No
A7: 46248.887 | B7: Sí | C7: 1 o 2 | D7: Spotify | E7: Todas las pago yo | F7: Menos de $10.000 | G7: 5 | H7: Sí, lo reviso seguido | I7: Menos de $10.000 | J7: Sí, una vez | K7: Menos de 1 mes | L7: 1 | M7: Esta semana | N7: Sí, más de una vez | O7: Sí | P7: 5 | Q7: No | R7: No comparto ninguna | S7: Nada, no llevo control | T7: Que me avise antes de cada cobro, Que me avise antes de que termine una prueba gratis | U7: Prefiero un pago único | V7: Celular, Computador | W7: 18 a 24 | X7: Estudio y trabajo
A8: 46248.889 | B8: Sí | C8: 5 o 6 | D8: Netflix, Disney+, Prime Video, YouTube Premium, ChatGPT u otra IA | E8: Algunas las comparto con familia o amigos | F8: Entre $35.000 y $50.000 | G8: 4 | H8: Lo hice una vez | I8: Entre $50.000 y $80.000 | J8: Sí, una vez | K8: Más de 6 meses | L8: Ninguna | M8: Esta semana | N8: Sí, una vez | O8: No | P8: 4 | Q8: Sí | R8: Nunca | S8: Reviso la app del banco | T8: Ver el total que gasto al mes, Que me avise antes de cada cobro, Ordenar las que comparto con otros | U8: Más de $3.000 al mes | V8: Celular | W8: 18 a 24 | X8: Solo trabajo | Y8: Pensé que gastaba menos en suscripciones pero al fin y al cabo son cosas que uno utiliza casi siempre. | Z8: si, claro.
A9: 46248.899 | B9: Sí | C9: 5 o 6 | D9: Netflix, Disney+, HBO Max, Prime Video, YouTube Premium, Juegos (PS Plus, Game Pass, etc.) | E9: La mayoría me las pagan a mí | F9: Entre $20.000 y $35.000 | G9: 4 | H9: Nunca lo he hecho | J9: Sí, una vez | K9: Entre 1 y 3 meses | L9: 3 | M9: Este mes | N9: No he usado pruebas gratis | O9: No | P9: 4 | Q9: Sí | R9: Nunca | S9: Nada, no llevo control | T9: Que me avise antes de cada cobro, Que me avise antes de que termine una prueba gratis, Recomendarme cuál me conviene cancelar | U9: Hasta $1.000 al mes | V9: Computador | W9: 18 a 24 | X9: Solo estudio
A10: 46248.899 | B10: Sí | C10: 5 o 6 | D10: Netflix, Spotify, Disney+, HBO Max, Prime Video, ChatGPT u otra IA | E10: La mayoría me las pagan a mí | F10: Entre $10.000 y $20.000 | G10: 3 | H10: Nunca lo he hecho | I10: Entre $20.000 y $35.000 | J10: Sí, varias veces | K10: Más de 6 meses | L10: Ninguna | M10: Hace 2 o 3 meses | N10: Sí, más de una vez | O10: Sí | P10: 3 | Q10: Sí | R10: Nunca | S10: Nada, no llevo control | T10: Ver el total que gasto al mes, Mostrarme cuánto uso realmente cada una | U10: Solo la usaría si es gratis | V10: Celular | W10: 18 a 24 | X10: Solo estudio | Y10: Usualmente en mi familia ocurre que compartimos las suscripciones, pero por no recordar las claves o cuentas, terminamos con dos cuentas distintas pagando 2 veces | Z10: (correo retirado)
A11: 46248.926 | B11: Sí | C11: 3 o 4 | D11: Netflix, Spotify, iCloud o Google One | E11: Es una mezcla | F11: Entre $35.000 y $50.000 | G11: 1 | H11: Nunca lo he hecho | I11: Menos de $10.000 | J11: Sí, varias veces | K11: Entre 1 y 3 meses | L11: Ninguna | M11: Esta semana | N11: Sí, más de una vez | O11: No | P11: 3 | Q11: Sí | R11: No comparto ninguna | S11: Nada, no llevo control | T11: Ver el total que gasto al mes | U11: Hasta $1.000 al mes | V11: Celular, Computador, Smart TV | W11: 18 a 24 | X11: Otro | Z11: (correo retirado)
A12: 46248.988 | B12: Sí | C12: 1 o 2 | D12: Spotify | E12: Todas las pago yo | F12: Menos de $10.000 | G12: 5 | H12: Sí, lo reviso seguido | I12: Menos de $10.000 | J12: Sí, una vez | K12: Menos de 1 mes | L12: Ninguna | M12: Esta semana | N12: Sí, una vez | O12: Sí | P12: 3 | Q12: Sí | R12: Nunca | S12: Lo tengo más o menos en la cabeza | T12: Que me avise antes de cada cobro, Que me avise antes de que termine una prueba gratis | U12: Hasta $1.000 al mes | V12: Celular | W12: 18 a 24 | X12: Otro
A13: 46249.011 | B13: Sí | C13: 1 o 2 | D13: iCloud o Google One, ChatGPT u otra IA, Uber one | E13: Todas las pago yo | F13: Entre $20.000 y $35.000 | G13: 5 | H13: Sí, lo reviso seguido | I13: Entre $20.000 y $35.000 | J13: Sí, una vez | K13: Menos de 1 mes | L13: Ninguna | M13: Este mes | N13: Sí, más de una vez | O13: No | P13: 2 | Q13: No | R13: No comparto ninguna | S13: Lo tengo más o menos en la cabeza | T13: Que me avise antes de cada cobro, Que me avise antes de que termine una prueba gratis | U13: Entre $1.000 y $3.000 al mes | V13: Celular | W13: 25 a 34 | X13: Solo estudio
A14: 46249.017 | B14: Sí | C14: 5 o 6 | D14: Spotify, YouTube Premium, iCloud o Google One, ChatGPT u otra IA, Apps del celular | E14: Todas las pago yo | F14: Entre $50.000 y $80.000 | G14: 5 | H14: Sí, lo reviso seguido | I14: Entre $50.000 y $80.000 | J14: Sí, varias veces | K14: No me ha pasado | L14: 4 o más | M14: Esta semana | N14: Sí, más de una vez | O14: No | P14: 1 | Q14: No | R14: Nunca | S14: Reviso la app del banco | T14: Que me avise antes de cada cobro, Recomendarme cuál me conviene cancelar | U14: Prefiero un pago único | V14: Celular, Computador, Smart TV | W14: 45 a 54 | X14: Solo trabajo | Y14: Que todo esté en una sola App con un precio único y económico | Z14: (correo retirado)
A15: 46249.039 | B15: Sí | C15: 1 o 2 | D15: Crunchyroll | E15: Todas las pago yo | F15: Menos de $10.000 | G15: 5 | H15: Nunca lo he hecho | I15: Menos de $10.000 | J15: No, nunca | K15: Menos de 1 mes | L15: Ninguna | M15: Esta semana | N15: No, nunca | O15: No | P15: 1 | Q15: Sí | R15: Nunca | S15: Lo tengo más o menos en la cabeza | T15: Que me avise antes de cada cobro, Que me avise antes de que termine una prueba gratis | U15: Hasta $1.000 al mes | V15: Celular | W15: 25 a 34 | X15: Estudio y trabajo
A16: 46249.093 | B16: No
A17: 46251.897 | B17: Sí | C17: 1 o 2 | D17: Spotify | E17: Todas las pago yo | F17: Menos de $10.000 | G17: 5 | H17: Nunca lo he hecho | I17: Menos de $10.000 | J17: No, nunca | K17: No me ha pasado | L17: Ninguna | M17: No me acuerdo | N17: No, nunca | O17: Sí | P17: 1 | Q17: No | R17: No comparto ninguna | S17: Uso una app hecha para eso | T17: Ver el total que gasto al mes, Que me avise antes de cada cobro | U17: Solo la usaría si es gratis | V17: Celular | W17: 18 a 24 | X17: Estudio y trabajo | Y17: (respuesta retirada) | Z17: Never! 🤮
A18: 46251.897 | B18: No
A19: 46251.899 | B19: Sí | C19: 3 o 4 | D19: Netflix, YouTube Premium, iCloud o Google One, ¡QIYI | E19: Todas las pago yo | F19: Entre $20.000 y $35.000 | G19: 4 | H19: Sí, lo reviso seguido | I19: Entre $20.000 y $35.000 | J19: Sí, una vez | K19: Entre 1 y 3 meses | L19: 1 | M19: Este mes | N19: Sí, más de una vez | O19: No | P19: 3 | Q19: No | R19: No comparto ninguna | S19: Lo tengo más o menos en la cabeza | T19: Que me avise antes de cada cobro, Que me avise antes de que termine una prueba gratis | U19: Solo la usaría si es gratis | V19: Celular | W19: 18 a 24 | X19: Solo estudio | Y19: Netflix está sobre valorado | Z19: (correo retirado)
A20: 46251.908 | B20: Sí | C20: 3 o 4 | D20: Netflix, Spotify, Gimnasio | E20: Algunas las comparto con familia o amigos | F20: Entre $10.000 y $20.000 | G20: 5 | H20: Sí, lo reviso seguido | I20: Entre $10.000 y $20.000 | J20: Sí, varias veces | K20: Menos de 1 mes | L20: 2 | M20: Esta semana | N20: Sí, una vez | O20: Sí | P20: 4 | Q20: Sí | R20: A veces | S20: Reviso la app del banco | T20: Que me avise antes de cada cobro, Que me avise antes de que termine una prueba gratis | U20: Entre $1.000 y $3.000 al mes | V20: Celular | W20: 25 a 34 | X20: Estudio y trabajo
A21: 46251.912 | B21: Sí | C21: 1 o 2 | D21: Netflix, YouTube Premium | E21: Algunas las comparto con familia o amigos | F21: Entre $10.000 y $20.000 | G21: 5 | H21: Sí, lo reviso seguido | I21: Entre $10.000 y $20.000 | J21: Sí, varias veces | K21: Entre 4 y 6 meses | L21: Ninguna | M21: Esta semana | N21: No, nunca | O21: Sí | P21: 3 | Q21: Sí | R21: Nunca | S21: Anoto en Excel o en notas del celular | T21: Ver el total que gasto al mes, Que me avise antes de cada cobro | U21: Más de $3.000 al mes | V21: Computador | W21: 25 a 34 | X21: Estudio y trabajo | Y21: Que te cobren recargo extra por dejar la app | Z21: (correo retirado)
A22: 46251.927 | B22: Sí | C22: 1 o 2 | D22: Tidal | E22: Todas las pago yo | F22: Menos de $10.000 | G22: 5 | H22: Sí, lo reviso seguido | I22: Menos de $10.000 | J22: Sí, una vez | K22: Menos de 1 mes | L22: Ninguna | M22: Esta semana | N22: Sí, más de una vez | O22: No | P22: 3 | Q22: No | R22: No comparto ninguna | S22: Lo tengo más o menos en la cabeza | T22: Que me avise antes de cada cobro, Que me avise antes de que termine una prueba gratis | U22: Entre $1.000 y $3.000 al mes | V22: Celular, Computador | W22: 18 a 24 | X22: Solo estudio | Y22: Las cagadas de prueba gratuitas de Crunchyroll al cancelarlas te la quitan enseguida no es como las demás que dura los 7 días | Z22: (correo retirado)
A23: 46251.927 | B23: No
A24: 46251.961 | B24: Sí | C24: 3 o 4 | D24: Netflix, Spotify, Disney+, HBO Max, Prime Video, ChatGPT u otra IA | E24: Es una mezcla | F24: Entre $20.000 y $35.000 | G24: 3 | H24: Nunca lo he hecho | I24: Entre $50.000 y $80.000 | J24: Sí, varias veces | K24: Entre 1 y 3 meses | L24: Ninguna | M24: Este mes | N24: Sí, una vez | O24: Sí | P24: 3 | Q24: Sí | R24: Nunca | S24: Lo tengo más o menos en la cabeza | T24: Que me avise antes de que termine una prueba gratis, Mostrarme cuánto uso realmente cada una, Ayudarme a cancelar | U24: Prefiero un pago único | V24: Celular, Computador, Smart TV | W24: 25 a 34 | X24: Solo trabajo | Y24: Me gustaría poder detectar fácilmente cuáles suscripciones realmente uso y cuáles podría cancelar.
A25: 46251.988 | B25: Sí | C25: 1 o 2 | D25: Prime Video, Apple Music | E25: Todas las pago yo | F25: Entre $35.000 y $50.000 | G25: 4 | H25: Sí, lo reviso seguido | I25: Entre $35.000 y $50.000 | J25: Sí, varias veces | K25: Menos de 1 mes | L25: 2 | M25: Esta semana | N25: Sí, más de una vez | O25: Sí | P25: 3 | Q25: No | R25: A veces | S25: Lo tengo más o menos en la cabeza | T25: Mostrarme cuánto uso realmente cada una, Recomendarme cuál me conviene cancelar | U25: Solo la usaría si es gratis | V25: Celular | W25: 18 a 24 | X25: Estudio y trabajo | Y25: Nada
A26: 46252.297 | B26: Sí | C26: 1 o 2 | D26: Prime Video | E26: La mayoría me las pagan a mí | F26: Entre $10.000 y $20.000 | G26: 4 | H26: Nunca lo he hecho | I26: Entre $10.000 y $20.000 | J26: No, nunca | K26: No me ha pasado | L26: Ninguna | M26: No me acuerdo | N26: No, nunca | O26: No | P26: 4 | Q26: Sí | R26: Nunca | S26: Nada, no llevo control | T26: Que me avise antes de cada cobro, Que me avise antes de que termine una prueba gratis | U26: Hasta $1.000 al mes | V26: Celular, Smart TV | W26: 18 a 24 | X26: Solo estudio | Z26: (correo retirado)
A27: 46252.302 | B27: Sí | C27: 1 o 2 | D27: Spotify, Vetflow | E27: Todas las pago yo | F27: Menos de $10.000 | G27: 5 | H27: Sí, lo reviso seguido | I27: Menos de $10.000 | J27: No, nunca | K27: No me ha pasado | L27: Ninguna | M27: Esta semana | N27: No, nunca | O27: No | P27: 1 | Q27: No | R27: No comparto ninguna | S27: Lo tengo más o menos en la cabeza | T27: Que me avise antes de cada cobro | U27: Entre $1.000 y $3.000 al mes | V27: Celular | W27: 18 a 24 | X27: Solo estudio | Z27: (correo retirado)
A28: 46252.302 | B28: No
A29: 46252.326 | B29: No
A30: 46252.554 | B30: Sí | C30: 1 o 2 | D30: iCloud o Google One, Apple Music | E30: Todas las pago yo | F30: Menos de $10.000 | G30: 5 | H30: Sí, lo reviso seguido | I30: Menos de $10.000 | J30: No, nunca | K30: No me ha pasado | L30: 1 | M30: Esta semana | N30: No, nunca | O30: No | P30: 3 | Q30: No | R30: No comparto ninguna | S30: Reviso la app del banco | T30: Que me avise antes de cada cobro, Que me avise antes de que termine una prueba gratis | U30: Entre $1.000 y $3.000 al mes | V30: Celular | W30: 18 a 24 | X30: Otro
A31: 46252.776 | B31: No
A32: 46252.777 | B32: No
A33: 46253.92 | B33: Sí | C33: 1 o 2 | D33: Spotify, Apps del celular | E33: Algunas las comparto con familia o amigos | F33: Menos de $10.000 | G33: 5 | H33: Sí, lo reviso seguido | I33: Menos de $10.000 | J33: No, nunca | K33: No me ha pasado | L33: Ninguna | M33: Esta semana | N33: Sí, una vez | O33: No | P33: 5 | Q33: Sí | R33: A veces | S33: Anoto en Excel o en notas del celular | T33: Ver el total que gasto al mes, Que me avise antes de que termine una prueba gratis, Recomendarme cuál me conviene cancelar | U33: Solo la usaría si es gratis | V33: Celular, Computador | W33: 18 a 24 | X33: Solo estudio
A34: 46253.92 | B34: Sí | C34: 1 o 2 | D34: Juegos (PS Plus, Game Pass, etc.), Apps del celular, | E34: Todas las pago yo | F34: Entre $10.000 y $20.000 | G34: 3 | H34: Nunca lo he hecho | I34: Entre $10.000 y $20.000 | J34: Sí, varias veces | K34: Menos de 1 mes | L34: Ninguna | M34: Esta semana | N34: Sí, más de una vez | O34: Sí | P34: 1 | Q34: No | R34: Nunca | S34: Nada, no llevo control | T34: Ver el total que gasto al mes, Que me avise antes de cada cobro, Que me avise antes de que termine una prueba gratis, Mostrarme cuánto uso realmente cada una, Recomendarme cuál me conviene cancelar, Ayudarme a cancelar | U34: Solo la usaría si es gratis | V34: Celular | W34: 18 a 24 | X34: Estudio y trabajo
A35: 46253.921 | B35: Sí | C35: 3 o 4 | D35: Netflix, Spotify, Juegos (PS Plus, Game Pass, etc.) | E35: Algunas las comparto con familia o amigos | F35: Menos de $10.000 | G35: 4 | H35: Sí, lo reviso seguido | I35: Entre $10.000 y $20.000 | J35: No estoy seguro | K35: Menos de 1 mes | L35: 1 | M35: Este mes | N35: No, nunca | O35: No | P35: 2 | Q35: Sí | R35: Nunca | S35: Uso una app hecha para eso | T35: Ver el total que gasto al mes, Que me avise antes de cada cobro, Que me avise antes de que termine una prueba gratis, Ayudarme a cancelar | U35: Entre $1.000 y $3.000 al mes | V35: Computador, Smart TV | W35: 18 a 24 | X35: Solo estudio | Y35: Mayormente aprovecho las ofertas que dan cada cierto tiempo y las aprovecho, desde que termina la oferta pagó solo un mes más y cambio de plataforma, me gusta ahorrar lo suficiente para dividir mis gastos. | Z35: (correo retirado)
A36: 46253.922 | B36: Sí | C36: 3 o 4 | D36: Netflix, Disney+, Paramount+ | E36: La mayoría me las pagan a mí | F36: Entre $20.000 y $35.000 | G36: 2 | H36: Nunca lo he hecho | I36: Entre $35.000 y $50.000 | J36: Sí, una vez | K36: Entre 4 y 6 meses | L36: Ninguna | M36: Esta semana | N36: No he usado pruebas gratis | O36: No | P36: 1 | Q36: Sí | R36: Nunca | S36: Nada, no llevo control | T36: Que me avise antes de cada cobro, Recomendarme cuál me conviene cancelar | U36: Entre $1.000 y $3.000 al mes | V36: Celular, Computador, Smart TV | W36: Menos de 18 | X36: Solo estudio
A37: 46253.924 | B37: Sí | C37: 1 o 2 | D37: YouTube Premium | E37: Algunas las comparto con familia o amigos | F37: Menos de $10.000 | G37: 5 | H37: Nunca lo he hecho | I37: Menos de $10.000 | J37: No, nunca | K37: No me ha pasado | L37: Ninguna | M37: Esta semana | N37: Sí, más de una vez | O37: No | P37: 2 | Q37: Sí | R37: Nunca | S37: Nada, no llevo control | T37: Ver el total que gasto al mes, Recomendarme cuál me conviene cancelar | U37: Más de $3.000 al mes | V37: Celular, Computador | W37: 18 a 24 | X37: Solo estudio | Z37: (correo retirado)
A38: 46253.925 | B38: Sí | C38: 1 o 2 | D38: iCloud o Google One, Private Relay (Separado de iCloud) | E38: Todas las pago yo | F38: Menos de $10.000 | G38: 5 | H38: Sí, lo reviso seguido | I38: Menos de $10.000 | J38: Sí, varias veces | K38: Entre 1 y 3 meses | L38: 2 | M38: Esta semana | N38: No, nunca | O38: No | P38: 1 | Q38: No | R38: No comparto ninguna | S38: Reviso la app del banco | T38: Que me avise antes de cada cobro | U38: Solo la usaría si es gratis | V38: Celular, Computador | W38: 18 a 24 | X38: Solo estudio | Y38: Private relay viene incluido en el plan 200GB, pero para incluirlo hay que pagar 800 pesos mas. Poreso esta separado de iCloud 200GB | Z38: (correo retirado)
A39: 46253.926 | B39: Sí | C39: 1 o 2 | D39: Spotify | E39: Todas las pago yo | F39: Menos de $10.000 | G39: 5 | H39: Nunca lo he hecho | I39: Menos de $10.000 | J39: No estoy seguro | K39: No me ha pasado | L39: Ninguna | M39: Esta semana | N39: Sí, una vez | O39: Sí | P39: 4 | Q39: No | R39: Nunca | S39: Lo tengo más o menos en la cabeza | T39: Ver el total que gasto al mes, Que me avise antes de cada cobro, Que me avise antes de que termine una prueba gratis, Mostrarme cuánto uso realmente cada una, Recomendarme cuál me conviene cancelar, Ayudarme a cancelar, Ordenar las que comparto con otros | U39: Entre $1.000 y $3.000 al mes | V39: Computador | W39: 18 a 24 | X39: Solo estudio
A40: 46253.928 | B40: Sí | C40: 1 o 2 | D40: Netflix, apple music | E40: Todas las pago yo | F40: Entre $10.000 y $20.000 | G40: 5 | H40: Lo hice una vez | I40: Entre $10.000 y $20.000 | J40: Sí, varias veces | K40: Entre 1 y 3 meses | L40: 1 | M40: Hace 2 o 3 meses | N40: Sí, más de una vez | O40: No | P40: 2 | Q40: Sí | R40: Nunca | S40: Reviso la app del banco | T40: Que me avise antes de cada cobro, Que me avise antes de que termine una prueba gratis | U40: Entre $1.000 y $3.000 al mes | V40: Celular, Computador, Smart TV | W40: 18 a 24 | X40: Estudio y trabajo | Y40: una prueba gratis de duolingo se acabó y me cobraron 50 lucas :( | Z40: (correo retirado)
...

Sheet Mapa
A1: Rango | B1: Punto medio ($) | D1: Esta hoja convierte cada rango en un número para poder promediar. Si cambias los rangos del formulario, actualízalos también acá.
A2: Menos de $10.000 | B2: 7500
A3: Entre $10.000 y $20.000 | B3: 15000
A4: Entre $20.000 y $35.000 | B4: 27500
A5: Entre $35.000 y $50.000 | B5: 42500
A6: Entre $50.000 y $80.000 | B6: 65000
A7: Más de $80.000 | B7: 95000

Sheet Calculos
A1: Estimado (P5) | B1: Real (P8) | C1: Diferencia (real - estimado) | D1: Estimado (solo pares) | E1: Real (solo pares)
A2: {=IFERROR(VLOOKUP(INDIRECT("'Respuestas de formulario 1'!F2:F"), Mapa!$A:$B, 2, FALSE), "")} -> 42500 | B2: {=IFERROR(VLOOKUP(INDIRECT("'Respuestas de formulario 1'!I2:I"), Mapa!$A:$B, 2, FALSE), "")} -> 95000 | C2: {=IF((A2:A1000<>"")*(B2:B1000<>""), B2:B1000-A2:A1000, "")} -> 52500 | D2: {=IF(C2:C1000="", "", A2:A1000)} -> 42500 | E2: {=IF(C2:C1000="", "", B2:B1000)} -> 95000
A3: 7500 | B3: 7500 | C3: 0 | D3: 7500 | E3: 7500
A4: 65000
A7: 7500 | B7: 7500 | C7: 0 | D7: 7500 | E7: 7500
A8: 42500 | B8: 65000 | C8: 22500 | D8: 42500 | E8: 65000
A9: 27500
A10: 15000 | B10: 27500 | C10: 12500 | D10: 15000 | E10: 27500
A11: 42500 | B11: 7500 | C11: -35000 | D11: 42500 | E11: 7500
A12: 7500 | B12: 7500 | C12: 0 | D12: 7500 | E12: 7500
A13: 27500 | B13: 27500 | C13: 0 | D13: 27500 | E13: 27500
A14: 65000 | B14: 65000 | C14: 0 | D14: 65000 | E14: 65000
A15: 7500 | B15: 7500 | C15: 0 | D15: 7500 | E15: 7500
A17: 7500 | B17: 7500 | C17: 0 | D17: 7500 | E17: 7500
A19: 27500 | B19: 27500 | C19: 0 | D19: 27500 | E19: 27500
A20: 15000 | B20: 15000 | C20: 0 | D20: 15000 | E20: 15000
A21: 15000 | B21: 15000 | C21: 0 | D21: 15000 | E21: 15000
A22: 7500 | B22: 7500 | C22: 0 | D22: 7500 | E22: 7500
A24: 27500 | B24: 65000 | C24: 37500 | D24: 27500 | E24: 65000
... A50: 27500 | B50: 27500 | C50: 0 | D50: 27500 | E50: 27500

Sheet Analisis
A1: ANÁLISIS DE LA ENCUESTA
A3: Respuestas totales (n) | B3: {=COUNTA(INDIRECT("'Respuestas de formulario 1'!A2:A"))} -> 49
A4: Con al menos una suscripción | B4: {=COUNTIF(INDIRECT("'Respuestas de formulario 1'!B2:B"), "Sí")} -> 38
A6: ★ HALLAZGO PRINCIPAL — ¿la gente sabe cuánto gasta?
A8: Respondieron ambas preguntas (P5 y P8) | B8: =COUNT(Calculos!C2:C1000) -> 36
A9: Gasto promedio ESTIMADO (solo pares) | B9: =IFERROR(AVERAGE(Calculos!D2:D1000),0) -> 19027.778
A10: Gasto promedio REAL (solo pares) | B10: =IFERROR(AVERAGE(Calculos!E2:E1000),0) -> 20902.778
A11: Mediana estimada (solo pares) | B11: =IFERROR(MEDIAN(Calculos!D2:D1000),0) -> 15000
A12: Mediana real (solo pares) | B12: =IFERROR(MEDIAN(Calculos!E2:E1000),0) -> 11250
A13: Diferencia promedio (real - estimado) | B13: =IFERROR(AVERAGE(Calculos!C2:C1000),0) -> 1875
A14: % de subestimación promedio | B14: =IFERROR(AVERAGE(Calculos!C2:C1000)/AVERAGE(Calculos!E2:E1000),0) -> 0.089700997
A15: Personas que SUBESTIMARON su gasto | B15: =COUNTIF(Calculos!C2:C1000, ">0") -> 7
A16: Personas que acertaron el rango | B16: =COUNTIF(Calculos!C2:C1000, "=0") -> 27
A17: Personas que sobrestimaron | B17: =COUNTIF(Calculos!C2:C1000, "<0") -> 2
A18: % que subestima su gasto real | B18: =IFERROR(COUNTIF(Calculos!C2:C1000, ">0")/COUNT(Calculos!C2:C1000),0) -> 0.19444444
A19: Frase lista para el informe: "El X% de los encuestados subestima su gasto real en suscripciones, con una diferencia promedio de $Y mensuales."
A22: FRECUENCIAS POR PREGUNTA
A24: P1. ¿Paga alguna suscripción?
A25: Opción | B25: Respuestas | C25: %
A26: Sí | B26: =COUNTIF(INDIRECT("'Respuestas de formulario 1'!B2:B"), $A26) -> 38 | C26: =IFERROR($B26/COUNTA(INDIRECT("'Respuestas de formulario 1'!B2:B")), 0) -> 0.7755102
A27: No | B27: =COUNTIF(INDIRECT("'Respuestas de formulario 1'!B2:B"), $A27) -> 11 | C27: =IFERROR($B27/COUNTA(INDIRECT("'Respuestas de formulario 1'!B2:B")), 0) -> 0.2244898
A28: Total | B28: =SUM(B26:B27) -> 49 | C28: =SUM(C26:C27) -> 1
A30: P2. ¿Cuántas suscripciones tiene?
A31: Opción | B31: Respuestas | C31: %
A32: 1 o 2 | B32: =COUNTIF(INDIRECT("'Respuestas de formulario 1'!C2:C"), $A32) -> 23 | C32: =IFERROR($B32/COUNTA(INDIRECT("'Respuestas de formulario 1'!C2:C")), 0) -> 0.60526316
A33: 3 o 4 | B33: =COUNTIF(INDIRECT("'Respuestas de formulario 1'!C2:C"), $A33) -> 9 | C33: =IFERROR($B33/COUNTA(INDIRECT("'Respuestas de formulario 1'!C2:C")), 0) -> 0.23684211
A34: 5 o 6 | B34: =COUNTIF(INDIRECT("'Respuestas de formulario 1'!C2:C"), $A34) -> 5 | C34: =IFERROR($B34/COUNTA(INDIRECT("'Respuestas de formulario 1'!C2:C")), 0) -> 0.13157895
A35: 7 a 9 | B35: =COUNTIF(INDIRECT("'Respuestas de formulario 1'!C2:C"), $A35) -> 1 | C35: =IFERROR($B35/COUNTA(INDIRECT("'Respuestas de formulario 1'!C2:C")), 0) -> 0.026315789
A36: 10 o más | B36: =COUNTIF(INDIRECT("'Respuestas de formulario 1'!C2:C"), $A36) -> 0 | C36: =IFERROR($B36/COUNTA(INDIRECT("'Respuestas de formulario 1'!C2:C")), 0) -> 0
A37: Total | B37: =SUM(B32:B36) -> 38 | C37: =SUM(C32:C36) -> 1
A39: P3. Qué servicios tiene (respuesta múltiple)
A40: Opción | B40: Respuestas | C40: %
A41: Netflix | B41: =COUNTIF(INDIRECT("'Respuestas de formulario 1'!D2:D"), "*"&$A41&"*") -> 17 | C41: =IFERROR($B41/COUNTA(INDIRECT("'Respuestas de formulario 1'!D2:D")), 0) -> 0.44736842
A42: Spotify | B42: =COUNTIF(INDIRECT("'Respuestas de formulario 1'!D2:D"), "*"&$A42&"*") -> 21 | C42: =IFERROR($B42/COUNTA(INDIRECT("'Respuestas de formulario 1'!D2:D")), 0) -> 0.55263158
A43: Disney+ | B43: =COUNTIF(INDIRECT("'Respuestas de formulario 1'!D2:D"), "*"&$A43&"*") -> 9 | C43: =IFERROR($B43/COUNTA(INDIRECT("'Respuestas de formulario 1'!D2:D")), 0) -> 0.23684211
A44: HBO Max | B44: =COUNTIF(INDIRECT("'Respuestas de formulario 1'!D2:D"), "*"&$A44&"*") -> 5 | C44: =IFERROR($B44/COUNTA(INDIRECT("'Respuestas de formulario 1'!D2:D")), 0) -> 0.13157895
A45: Prime Video | B45: =COUNTIF(INDIRECT("'Respuestas de formulario 1'!D2:D"), "*"&$A45&"*") -> 7 | C45: =IFERROR($B45/COUNTA(INDIRECT("'Respuestas de formulario 1'!D2:D")), 0) -> 0.18421053
A46: YouTube Premium | B46: =COUNTIF(INDIRECT("'Respuestas de formulario 1'!D2:D"), "*"&$A46&"*") -> 9 | C46: =IFERROR($B46/COUNTA(INDIRECT("'Respuestas de formulario 1'!D2:D")), 0) -> 0.23684211
A47: iCloud o Google One | B47: =COUNTIF(INDIRECT("'Respuestas de formulario 1'!D2:D"), "*"&$A47&"*") -> 10 | C47: =IFERROR($B47/COUNTA(INDIRECT("'Respuestas de formulario 1'!D2:D")), 0) -> 0.26315789
A48: ChatGPT u otra IA | B48: =COUNTIF(INDIRECT("'Respuestas de formulario 1'!D2:D"), "*"&$A48&"*") -> 9 | C48: =IFERROR($B48/COUNTA(INDIRECT("'Respuestas de formulario 1'!D2:D")), 0) -> 0.23684211
...

Sheet Graficos
A1: GRÁFICOS DE LA ENCUESTA
A2: Se actualizan solos cuando llegan respuestas nuevas. Clic derecho sobre un gráfico → Copiar → pegar en el informe.
A4: Auxiliar — gasto estimado vs real
A5: Rango | B5: Estimado (P5) | C5: Real (P8)
A6: Menos de $10.000 | B6: =COUNTIF(INDIRECT("'Respuestas de formulario 1'!F2:F"), $A6) -> 17 | C6: =COUNTIF(INDIRECT("'Respuestas de formulario 1'!I2:I"), $A6) -> 18
A7: Entre $10.000 y $20.000 | B7: =COUNTIF(INDIRECT("'Respuestas de formulario 1'!F2:F"), $A7) -> 8 | C7: =COUNTIF(INDIRECT("'Respuestas de formulario 1'!I2:I"), $A7) -> 7
A8: Entre $20.000 y $35.000 | B8: =COUNTIF(INDIRECT("'Respuestas de formulario 1'!F2:F"), $A8) -> 6 | C8: =COUNTIF(INDIRECT("'Respuestas de formulario 1'!I2:I"), $A8) -> 5
A9: Entre $35.000 y $50.000 | B9: =COUNTIF(INDIRECT("'Respuestas de formulario 1'!F2:F"), $A9) -> 4 | C9: =COUNTIF(INDIRECT("'Respuestas de formulario 1'!I2:I"), $A9) -> 2
A10: Entre $50.000 y $80.000 | B10: =COUNTIF(INDIRECT("'Respuestas de formulario 1'!F2:F"), $A10) -> 3 | C10: =COUNTIF(INDIRECT("'Respuestas de formulario 1'!I2:I"), $A10) -> 3
A11: Más de $80.000 | B11: =COUNTIF(INDIRECT("'Respuestas de formulario 1'!F2:F"), $A11) -> 0 | C11: =COUNTIF(INDIRECT("'Respuestas de formulario 1'!I2:I"), $A11) -> 1
A14: Auxiliar — pagó por algo sin usar, según cuántas suscripciones tiene
A15: Suscripciones | B15: Ha pagado sin usar | C15: Nunca le pasó
A16: 1 o 2 | B16: {=COUNTIFS(INDIRECT("'Respuestas de formulario 1'!C2:C"), "1 o 2", INDIRECT("'Respuestas de formulario 1'!J2:J"), "Sí, varias veces")+COUNTIFS(INDIRECT("'Respuestas de formulario 1'!C2:C"), "1 o 2", INDIRECT("'Respuestas de formulario 1'!J2:J"), "Sí, una vez")} -> 12 | C16: {=COUNTIFS(INDIRECT("'Respuestas de formulario 1'!C2:C"), "1 o 2", INDIRECT("'Respuestas de formulario 1'!J2:J"), "No, nunca")} -> 10
A17: 3 o más | B17: {=COUNTIFS(INDIRECT("'Respuestas de formulario 1'!C2:C"), "3 o 4", INDIRECT("'Respuestas de formulario 1'!J2:J"), "Sí, varias veces")+COUNTIFS(INDIRECT("'Respuestas de formulario 1'!C2:C"), "3 o 4", INDIRECT("'Respuestas de formulario 1'!J2:J"), "Sí, una vez")+COUNTIFS(INDIRECT("'Respuestas de formulario 1'!C2:C"), "5 o 6", INDIRECT("'Respuestas de formulario 1'!J2:J"), "Sí, varias veces")+COUNTIFS(INDIRECT("'Respuestas de formulario 1'!C2:C"), "5 o 6", INDIRECT("'Respuestas de formulario 1'!J2:J"), "Sí, una vez")+COUNTIFS(INDIRECT("'Respuestas de formulario 1'!C2:C"), "7 a 9", INDIRECT("'Respuestas de formulario 1'!J2:J"), "Sí, varias veces")+COUNTIFS(INDIRECT("'Respuestas de formulario 1'!C2:C"), "7 a 9", INDIRECT("'Respuestas de formulario 1'!J2:J"), "Sí, una vez")+COUNTIFS(INDIRECT("'Respuestas de formulario 1'!C2:C"), "10 o más", INDIRECT("'Respuestas de formulario 1'!J2:J"), "Sí, varias veces")+COUNTIFS(INDIRECT("'Respuestas de formulario 1'!C2:C"), "10 o más", INDIRECT("'Respuestas de formulario 1'!J2:J"), "Sí, una vez")} -> 14 | C17: {=COUNTIFS(INDIRECT("'Respuestas de formulario 1'!C2:C"), "3 o 4", INDIRECT("'Respuestas de formulario 1'!J2:J"), "No, nunca")+COUNTIFS(INDIRECT("'Respuestas de formulario 1'!C2:C"), "5 o 6", INDIRECT("'Respuestas de formulario 1'!J2:J"), "No, nunca")+COUNTIFS(INDIRECT("'Respuestas de formulario 1'!C2:C"), "7 a 9", INDIRECT("'Respuestas de formulario 1'!J2:J"), "No, nunca")+COUNTIFS(INDIRECT("'Respuestas de formulario 1'!C2:C"), "10 o más", INDIRECT("'Respuestas de formulario 1'!J2:J"), "No, nunca")} -> 0
